Workbook
Name SegmentaciónDeDatos_DESEMPEÑO: #N/A
Name SegmentaciónDeDatos_PERIODO: #N/A

Sheet INICIO
B7: SEDE: | D7: DOCENTE:
B8: ASIGNATURA: | D8: GRADO: | F8: GRUPO:
D20: =+ESTADISTICA!A4 -> DESEMPEÑOS | E20: =+ESTADISTICA!B4 -> PER. 01 | G20: DESEMPEÑOS | H20: =+ESTADISTICA!E4 -> FINAL
D21: =+ESTADISTICA!A5 -> BAJO | E21: =(+ESTADISTICA!B5/$E$25) -> #DIV/0! | G21: BAJO | H21: =(+ESTADISTICA!E5/$E$25) -> #DIV/0!
D22: =+ESTADISTICA!A6 -> BASICO | E22: =(+ESTADISTICA!B6/$E$25) -> #DIV/0! | G22: BASICO | H22: =(+ESTADISTICA!E6/$E$25) -> #DIV/0!
D23: =+ESTADISTICA!A7 -> ALTO | E23: =(+ESTADISTICA!B7/$E$25) -> #DIV/0! | G23: ALTO | H23: =(+ESTADISTICA!E7/$E$25) -> #DIV/0!
D24: =+ESTADISTICA!A8 -> SUPERIOR | E24: =(+ESTADISTICA!B8/$E$25) -> #DIV/0! | G24: SUPERIOR | H24: =(+ESTADISTICA!E8/$E$25) -> #DIV/0!
D25: TOTALES… | E25: =+ESTADISTICA!B9 -> 0 | G25: TOTALES… | H25: =+ESTADISTICA!E9 -> 0
D27: DESEMPEÑOS | E27: =+ESTADISTICA!C4 -> PER. 02
D28: BAJO | E28: =(+ESTADISTICA!C5/$E$25) -> #DIV/0!
D29: BASICO | E29: =(+ESTADISTICA!C6/$E$25) -> #DIV/0!
D30: ALTO | E30: =(+ESTADISTICA!C7/$E$25) -> #DIV/0!
D31: SUPERIOR | E31: =(+ESTADISTICA!C8/$E$25) -> #DIV/0!
D32: TOTALES… | E32: =+ESTADISTICA!C9 -> 0
D34: DESEMPEÑOS | E34: =+ESTADISTICA!D4 -> PER. 03
D35: BAJO | E35: =(+ESTADISTICA!D5/$E$25) -> #DIV/0!
D36: BASICO | E36: =(+ESTADISTICA!D6/$E$25) -> #DIV/0!
D37: ALTO | E37: =(+ESTADISTICA!D7/$E$25) -> #DIV/0!
D38: SUPERIOR | E38: =(+ESTADISTICA!D8/$E$25) -> #DIV/0!
D39: TOTALES… | E39: =+ESTADISTICA!D9 -> 0

Sheet PERIODO 01
C1: COGNITIVAS | S1: PROCEDIMENTALES | Y1: AXIOLÓGICAS | AE1: NOTA PARCIAL | AF1: ASPE | AG1: NOT FINAL PERIODO
C2: Nº ACT | D2: Descripción de la Actividad realizada para cada Nota | S2: Nº ACT | T2: Descripción de la Actividad realizada para cada Nota | Y2: Nº ACT | Z2: Descripción de la Actividad realizada para cada Nota
A3: =CONCATENATE(INICIO!B7," ",INICIO!C7) -> SEDE: | C3: NOTA1 | S3: NOTA1 | Y3: NOTA1
A4: =CONCATENATE(INICIO!D7," ",INICIO!E7) -> DOCENTE: | C4: NOTA 2 | S4: NOTA2 | Y4: NOTA2
A5: =CONCATENATE(INICIO!B8," ",INICIO!C8) -> ASIGNATURA: | C5: NOTA 3 | S5: NOTA3 | Y5: NOTA3
A6: =CONCATENATE(INICIO!D8,INICIO!E8," ",INICIO!F8,INICIO!G8) -> GRADO: GRUPO: | C6: NOTA 4 | S6: NOTA4 | Y6: NOTA4
A7: Periodo 01 | C7: NOTA 5 | S7: NOTA5 | Y7: NOTA5
C8: NOTA 1 | E8: NOTA 2 | G8: NOTA 3 | I8: NOTA 4 | K8: NOTA 5 | R8: N.P | S8: NOTA 1 | T8: NOTA 2 | U8: NOTA 3 | V8: NOTA 4 | W8: NOTA 5 | X8: N.P | Y8: NOTA 1 | Z8: NOTA 2 | AA8: NOTA 3 | AB8: NOTA 4 | AC8: NOTA 5 | AD8: N.P
A9: NO | B9: ESTUDIANTE | C9: NI | D9: AC | E9: NI | F9: AC | G9: NI | H9: AC | I9: NI | J9: AC | K9: NI | L9: AC | M9: n1 | N9: n2 | O9: n3 | P9: n4 | Q9: n5
A10: 1 | M10: =IF(ISBLANK(C10),"",IF(C10>D10,C10,D10)) | N10: =IF(ISBLANK(E10)," ",IF(E10>F10,E10,F10)) | O10: =IF(ISBLANK(G10),"",IF(G10>H10,G10,H10)) | P10: =IF(ISBLANK(I10),"",IF(I10>J10,I10,J10)) | Q10: =IF(ISBLANK(K10),"",IF(K10>L10,K10,L10)) | R10: =AVERAGE(M10:Q10) -> #DIV/0! | X10: =AVERAGE(S10:W10) -> #DIV/0! | AD10: =AVERAGE(Y10:AC10) -> #DIV/0! | AE10: =R10*0.5+X10*0.3+AD10*0.2 -> #DIV/0! | AG10: =IF(AE10>AF10,AE10,AF10) -> #DIV/0!
A11: 2 | M11: =IF(ISBLANK(C11),"",IF(C11>D11,C11,D11)) | N11: =IF(ISBLANK(E11)," ",IF(E11>F11,E11,F11)) | O11: =IF(ISBLANK(G11),"",IF(G11>H11,G11,H11)) | P11: =IF(ISBLANK(I11),"",IF(I11>J11,I11,J11)) | Q11: =IF(ISBLANK(K11),"",IF(K11>L11,K11,L11)) | R11: =AVERAGE(M11:Q11) -> #DIV/0! | X11: =AVERAGE(S11:W11) -> #DIV/0! | AD11: =AVERAGE(Y11:AC11) -> #DIV/0! | AE11: =R11*0.5+X11*0.3+AD11*0.2 -> #DIV/0! | AG11: =IF(AE11>AF11,AE11,AF11) -> #DIV/0!
A12: 3 | M12: =IF(ISBLANK(C12),"",IF(C12>D12,C12,D12)) | N12: =IF(ISBLANK(E12)," ",IF(E12>F12,E12,F12)) | O12: =IF(ISBLANK(G12),"",IF(G12>H12,G12,H12)) | P12: =IF(ISBLANK(I12),"",IF(I12>J12,I12,J12)) | Q12: =IF(ISBLANK(K12),"",IF(K12>L12,K12,L12)) | R12: =AVERAGE(M12:Q12) -> #DIV/0! | X12: =AVERAGE(S12:W12) -> #DIV/0! | AD12: =AVERAGE(Y12:AC12) -> #DIV/0! | AE12: =R12*0.5+X12*0.3+AD12*0.2 -> #DIV/0! | AG12: =IF(AE12>AF12,AE12,AF12) -> #DIV/0!
A13: 4 | M13: =IF(ISBLANK(C13),"",IF(C13>D13,C13,D13)) | N13: =IF(ISBLANK(E13)," ",IF(E13>F13,E13,F13)) | O13: =IF(ISBLANK(G13),"",IF(G13>H13,G13,H13)) | P13: =IF(ISBLANK(I13),"",IF(I13>J13,I13,J13)) | Q13: =IF(ISBLANK(K13),"",IF(K13>L13,K13,L13)) | R13: =AVERAGE(M13:Q13) -> #DIV/0! | X13: =AVERAGE(S13:W13) -> #DIV/0! | AD13: =AVERAGE(Y13:AC13) -> #DIV/0! | AE13: =R13*0.5+X13*0.3+AD13*0.2 -> #DIV/0! | AG13: =IF(AE13>AF13,AE13,AF13) -> #DIV/0!
A14: 5 | M14: =IF(ISBLANK(C14),"",IF(C14>D14,C14,D14)) | N14: =IF(ISBLANK(E14)," ",IF(E14>F14,E14,F14)) | O14: =IF(ISBLANK(G14),"",IF(G14>H14,G14,H14)) | P14: =IF(ISBLANK(I14),"",IF(I14>J14,I14,J14)) | Q14: =IF(ISBLANK(K14),"",IF(K14>L14,K14,L14)) | R14: =AVERAGE(M14:Q14) -> #DIV/0! | X14: =AVERAGE(S14:W14) -> #DIV/0! | AD14: =AVERAGE(Y14:AC14) -> #DIV/0! | AE14: =R14*0.5+X14*0.3+AD14*0.2 -> #DIV/0! | AG14: =IF(AE14>AF14,AE14,AF14) -> #DIV/0!
A15: 6 | M15: =IF(ISBLANK(C15),"",IF(C15>D15,C15,D15)) | N15: =IF(ISBLANK(E15)," ",IF(E15>F15,E15,F15)) | O15: =IF(ISBLANK(G15),"",IF(G15>H15,G15,H15)) | P15: =IF(ISBLANK(I15),"",IF(I15>J15,I15,J15)) | Q15: =IF(ISBLANK(K15),"",IF(K15>L15,K15,L15)) | R15: =AVERAGE(M15:Q15) -> #DIV/0! | X15: =AVERAGE(S15:W15) -> #DIV/0! | AD15: =AVERAGE(Y15:AC15) -> #DIV/0! | AE15: =R15*0.5+X15*0.3+AD15*0.2 -> #DIV/0! | AG15: =IF(AE15>AF15,AE15,AF15) -> #DIV/0!
A16: 7 | M16: =IF(ISBLANK(C16),"",IF(C16>D16,C16,D16)) | N16: =IF(ISBLANK(E16)," ",IF(E16>F16,E16,F16)) | O16: =IF(ISBLANK(G16),"",IF(G16>H16,G16,H16)) | P16: =IF(ISBLANK(I16),"",IF(I16>J16,I16,J16)) | Q16: =IF(ISBLANK(K16),"",IF(K16>L16,K16,L16)) | R16: =AVERAGE(M16:Q16) -> #DIV/0! | X16: =AVERAGE(S16:W16) -> #DIV/0! | AD16: =AVERAGE(Y16:AC16) -> #DIV/0! | AE16: =R16*0.5+X16*0.3+AD16*0.2 -> #DIV/0! | AG16: =IF(AE16>AF16,AE16,AF16) -> #DIV/0!
A17: 8 | M17: =IF(ISBLANK(C17),"",IF(C17>D17,C17,D17)) | N17: =IF(ISBLANK(E17)," ",IF(E17>F17,E17,F17)) | O17: =IF(ISBLANK(G17),"",IF(G17>H17,G17,H17)) | P17: =IF(ISBLANK(I17),"",IF(I17>J17,I17,J17)) | Q17: =IF(ISBLANK(K17),"",IF(K17>L17,K17,L17)) | R17: =AVERAGE(M17:Q17) -> #DIV/0! | X17: =AVERAGE(S17:W17) -> #DIV/0! | AD17: =AVERAGE(Y17:AC17) -> #DIV/0! | AE17: =R17*0.5+X17*0.3+AD17*0.2 -> #DIV/0! | AG17: =IF(AE17>AF17,AE17,AF17) -> #DIV/0!
A18: 9 | M18: =IF(ISBLANK(C18),"",IF(C18>D18,C18,D18)) | N18: =IF(ISBLANK(E18)," ",IF(E18>F18,E18,F18)) | O18: =IF(ISBLANK(G18),"",IF(G18>H18,G18,H18)) | P18: =IF(ISBLANK(I18),"",IF(I18>J18,I18,J18)) | Q18: =IF(ISBLANK(K18),"",IF(K18>L18,K18,L18)) | R18: =AVERAGE(M18:Q18) -> #DIV/0! | X18: =AVERAGE(S18:W18) -> #DIV/0! | AD18: =AVERAGE(Y18:AC18) -> #DIV/0! | AE18: =R18*0.5+X18*0.3+AD18*0.2 -> #DIV/0! | AG18: =IF(AE18>AF18,AE18,AF18) -> #DIV/0!
A19: 10 | M19: =IF(ISBLANK(C19),"",IF(C19>D19,C19,D19)) | N19: =IF(ISBLANK(E19)," ",IF(E19>F19,E19,F19)) | O19: =IF(ISBLANK(G19),"",IF(G19>H19,G19,H19)) | P19: =IF(ISBLANK(I19),"",IF(I19>J19,I19,J19)) | Q19: =IF(ISBLANK(K19),"",IF(K19>L19,K19,L19)) | R19: =AVERAGE(M19:Q19) -> #DIV/0! | X19: =AVERAGE(S19:W19) -> #DIV/0! | AD19: =AVERAGE(Y19:AC19) -> #DIV/0! | AE19: =R19*0.5+X19*0.3+AD19*0.2 -> #DIV/0! | AG19: =IF(AE19>AF19,AE19,AF19) -> #DIV/0!
A20: 11 | M20: =IF(ISBLANK(C20),"",IF(C20>D20,C20,D20)) | N20: =IF(ISBLANK(E20)," ",IF(E20>F20,E20,F20)) | O20: =IF(ISBLANK(G20),"",IF(G20>H20,G20,H20)) | P20: =IF(ISBLANK(I20),"",IF(I20>J20,I20,J20)) | Q20: =IF(ISBLANK(K20),"",IF(K20>L20,K20,L20)) | R20: =AVERAGE(M20:Q20) -> #DIV/0! | X20: =AVERAGE(S20:W20) -> #DIV/0! | AD20: =AVERAGE(Y20:AC20) -> #DIV/0! | AE20: =R20*0.5+X20*0.3+AD20*0.2 -> #DIV/0! | AG20: =IF(AE20>AF20,AE20,AF20) -> #DIV/0!
A21: 12 | M21: =IF(ISBLANK(C21),"",IF(C21>D21,C21,D21)) | N21: =IF(ISBLANK(E21)," ",IF(E21>F21,E21,F21)) | O21: =IF(ISBLANK(G21),"",IF(G21>H21,G21,H21)) | P21: =IF(ISBLANK(I21),"",IF(I21>J21,I21,J21)) | Q21: =IF(ISBLANK(K21),"",IF(K21>L21,K21,L21)) | R21: =AVERAGE(M21:Q21) -> #DIV/0! | X21: =AVERAGE(S21:W21) -> #DIV/0! | AD21: =AVERAGE(Y21:AC21) -> #DIV/0! | AE21: =R21*0.5+X21*0.3+AD21*0.2 -> #DIV/0! | AG21: =IF(AE21>AF21,AE21,AF21) -> #DIV/0!
... A49: 40 | M49: =IF(ISBLANK(C49),"",IF(C49>D49,C49,D49)) | N49: =IF(ISBLANK(E49)," ",IF(E49>F49,E49,F49)) | O49: =IF(ISBLANK(G49),"",IF(G49>H49,G49,H49)) | P49: =IF(ISBLANK(I49),"",IF(I49>J49,I49,J49)) | Q49: =IF(ISBLANK(K49),"",IF(K49>L49,K49,L49)) | R49: =AVERAGE(M49:Q49) -> #DIV/0! | X49: =AVERAGE(S49:W49) -> #DIV/0! | AD49: =AVERAGE(Y49:AC49) -> #DIV/0! | AE49: =R49*0.5+X49*0.3+AD49*0.2 -> #DIV/0! | AG49: =IF(AE49>AF49,AE49,AF49) -> #DIV/0!

Sheet PERIODO 02
C1: COGNITIVAS | S1: PROCEDIMENTALES | Y1: AXIOLÓGICAS | AE1: NOTA PARCIAL | AF1: ASPE | AG1: NOT FINAL PERIODO
C2: Nº ACT | D2: Descripción de la Actividad realizada para cada Nota | S2: Nº ACT | T2: Descripción de la Actividad realizada para cada Nota | Y2: Nº ACT | Z2: Descripción de la Actividad realizada para cada Nota
A3: =CONCATENATE(INICIO!B7," ",INICIO!C7) -> SEDE: | C3: NOTA1 | S3: NOTA1 | Y3: NOTA1
A4: =CONCATENATE(INICIO!D7," ",INICIO!E7) -> DOCENTE: | C4: NOTA 2 | S4: NOTA2 | Y4: NOTA2
A5: =CONCATENATE(INICIO!B8," ",INICIO!C8) -> ASIGNATURA: | C5: NOTA 3 | S5: NOTA3 | Y5: NOTA3
A6: =CONCATENATE(INICIO!D8,INICIO!E8," ",INICIO!F8,INICIO!G8) -> GRADO: GRUPO: | C6: NOTA 4 | S6: NOTA4 | Y6: NOTA4
A7: Periodo 02 | C7: NOTA 5 | S7: NOTA5 | Y7: NOTA5
C8: NOTA 1 | E8: NOTA 2 | G8: NOTA 3 | I8: NOTA 4 | K8: NOTA 5 | R8: N.P | S8: NOTA 1 | T8: NOTA 2 | U8: NOTA 3 | V8: NOTA 4 | W8: NOTA 5 | X8: N.P | Y8: NOTA 1 | Z8: NOTA 2 | AA8: NOTA 3 | AB8: NOTA 4 | AC8: NOTA 5 | AD8: N.P
A9: NO | B9: ESTUDIANTE | C9: NI | D9: AC | E9: NI | F9: AC | G9: NI | H9: AC | I9: NI | J9: AC | K9: NI | L9: AC | M9: n1 | N9: n2 | O9: n3 | P9: n4 | Q9: n5
A10: 1 | B10: =+'PERIODO 01'!B10 -> 0 | M10: =IF(ISBLANK(C10),"",IF(C10>D10,C10,D10)) | N10: =IF(ISBLANK(E10)," ",IF(E10>F10,E10,F10)) | O10: =IF(ISBLANK(G10),"",IF(G10>H10,G10,H10)) | P10: =IF(ISBLANK(I10),"",IF(I10>J10,I10,J10)) | Q10: =IF(ISBLANK(K10),"",IF(K10>L10,K10,L10)) | R10: =AVERAGE(M10:Q10) -> #DIV/0! | X10: =AVERAGE(S10:W10) -> #DIV/0! | AD10: =AVERAGE(Y10:AC10) -> #DIV/0! | AE10: =R10*0.5+X10*0.3+AD10*0.2 -> #DIV/0! | AG10: =IF(AE10>AF10,AE10,AF10) -> #DIV/0!
A11: 2 | B11: =+'PERIODO 01'!B11 -> 0 | M11: =IF(ISBLANK(C11),"",IF(C11>D11,C11,D11)) | N11: =IF(ISBLANK(E11)," ",IF(E11>F11,E11,F11)) | O11: =IF(ISBLANK(G11),"",IF(G11>H11,G11,H11)) | P11: =IF(ISBLANK(I11),"",IF(I11>J11,I11,J11)) | Q11: =IF(ISBLANK(K11),"",IF(K11>L11,K11,L11)) | R11: =AVERAGE(M11:Q11) -> #DIV/0! | X11: =AVERAGE(S11:W11) -> #DIV/0! | AD11: =AVERAGE(Y11:AC11) -> #DIV/0! | AE11: =R11*0.5+X11*0.3+AD11*0.2 -> #DIV/0! | AG11: =IF(AE11>AF11,AE11,AF11) -> #DIV/0!
A12: 3 | B12: =+'PERIODO 01'!B12 -> 0 | M12: =IF(ISBLANK(C12),"",IF(C12>D12,C12,D12)) | N12: =IF(ISBLANK(E12)," ",IF(E12>F12,E12,F12)) | O12: =IF(ISBLANK(G12),"",IF(G12>H12,G12,H12)) | P12: =IF(ISBLANK(I12),"",IF(I12>J12,I12,J12)) | Q12: =IF(ISBLANK(K12),"",IF(K12>L12,K12,L12)) | R12: =AVERAGE(M12:Q12) -> #DIV/0! | X12: =AVERAGE(S12:W12) -> #DIV/0! | AD12: =AVERAGE(Y12:AC12) -> #DIV/0! | AE12: =R12*0.5+X12*0.3+AD12*0.2 -> #DIV/0! | AG12: =IF(AE12>AF12,AE12,AF12) -> #DIV/0!
A13: 4 | B13: =+'PERIODO 01'!B13 -> 0 | M13: =IF(ISBLANK(C13),"",IF(C13>D13,C13,D13)) | N13: =IF(ISBLANK(E13)," ",IF(E13>F13,E13,F13)) | O13: =IF(ISBLANK(G13),"",IF(G13>H13,G13,H13)) | P13: =IF(ISBLANK(I13),"",IF(I13>J13,I13,J13)) | Q13: =IF(ISBLANK(K13),"",IF(K13>L13,K13,L13)) | R13: =AVERAGE(M13:Q13) -> #DIV/0! | X13: =AVERAGE(S13:W13) -> #DIV/0! | AD13: =AVERAGE(Y13:AC13) -> #DIV/0! | AE13: =R13*0.5+X13*0.3+AD13*0.2 -> #DIV/0! | AG13: =IF(AE13>AF13,AE13,AF13) -> #DIV/0!
A14: 5 | B14: =+'PERIODO 01'!B14 -> 0 | M14: =IF(ISBLANK(C14),"",IF(C14>D14,C14,D14)) | N14: =IF(ISBLANK(E14)," ",IF(E14>F14,E14,F14)) | O14: =IF(ISBLANK(G14),"",IF(G14>H14,G14,H14)) | P14: =IF(ISBLANK(I14),"",IF(I14>J14,I14,J14)) | Q14: =IF(ISBLANK(K14),"",IF(K14>L14,K14,L14)) | R14: =AVERAGE(M14:Q14) -> #DIV/0! | X14: =AVERAGE(S14:W14) -> #DIV/0! | AD14: =AVERAGE(Y14:AC14) -> #DIV/0! | AE14: =R14*0.5+X14*0.3+AD14*0.2 -> #DIV/0! | AG14: =IF(AE14>AF14,AE14,AF14) -> #DIV/0!
A15: 6 | B15: =+'PERIODO 01'!B15 -> 0 | M15: =IF(ISBLANK(C15),"",IF(C15>D15,C15,D15)) | N15: =IF(ISBLANK(E15)," ",IF(E15>F15,E15,F15)) | O15: =IF(ISBLANK(G15),"",IF(G15>H15,G15,H15)) | P15: =IF(ISBLANK(I15),"",IF(I15>J15,I15,J15)) | Q15: =IF(ISBLANK(K15),"",IF(K15>L15,K15,L15)) | R15: =AVERAGE(M15:Q15) -> #DIV/0! | X15: =AVERAGE(S15:W15) -> #DIV/0! | AD15: =AVERAGE(Y15:AC15) -> #DIV/0! | AE15: =R15*0.5+X15*0.3+AD15*0.2 -> #DIV/0! | AG15: =IF(AE15>AF15,AE15,AF15) -> #DIV/0!
A16: 7 | B16: =+'PERIODO 01'!B16 -> 0 | M16: =IF(ISBLANK(C16),"",IF(C16>D16,C16,D16)) | N16: =IF(ISBLANK(E16)," ",IF(E16>F16,E16,F16)) | O16: =IF(ISBLANK(G16),"",IF(G16>H16,G16,H16)) | P16: =IF(ISBLANK(I16),"",IF(I16>J16,I16,J16)) | Q16: =IF(ISBLANK(K16),"",IF(K16>L16,K16,L16)) | R16: =AVERAGE(M16:Q16) -> #DIV/0! | X16: =AVERAGE(S16:W16) -> #DIV/0! | AD16: =AVERAGE(Y16:AC16) -> #DIV/0! | AE16: =R16*0.5+X16*0.3+AD16*0.2 -> #DIV/0! | AG16: =IF(AE16>AF16,AE16,AF16) -> #DIV/0!
A17: 8 | B17: =+'PERIODO 01'!B17 -> 0 | M17: =IF(ISBLANK(C17),"",IF(C17>D17,C17,D17)) | N17: =IF(ISBLANK(E17)," ",IF(E17>F17,E17,F17)) | O17: =IF(ISBLANK(G17),"",IF(G17>H17,G17,H17)) | P17: =IF(ISBLANK(I17),"",IF(I17>J17,I17,J17)) | Q17: =IF(ISBLANK(K17),"",IF(K17>L17,K17,L17)) | R17: =AVERAGE(M17:Q17) -> #DIV/0! | X17: =AVERAGE(S17:W17) -> #DIV/0! | AD17: =AVERAGE(Y17:AC17) -> #DIV/0! | AE17: =R17*0.5+X17*0.3+AD17*0.2 -> #DIV/0! | AG17: =IF(AE17>AF17,AE17,AF17) -> #DIV/0!
A18: 9 | B18: =+'PERIODO 01'!B18 -> 0 | M18: =IF(ISBLANK(C18),"",IF(C18>D18,C18,D18)) | N18: =IF(ISBLANK(E18)," ",IF(E18>F18,E18,F18)) | O18: =IF(ISBLANK(G18),"",IF(G18>H18,G18,H18)) | P18: =IF(ISBLANK(I18),"",IF(I18>J18,I18,J18)) | Q18: =IF(ISBLANK(K18),"",IF(K18>L18,K18,L18)) | R18: =AVERAGE(M18:Q18) -> #DIV/0! | X18: =AVERAGE(S18:W18) -> #DIV/0! | AD18: =AVERAGE(Y18:AC18) -> #DIV/0! | AE18: =R18*0.5+X18*0.3+AD18*0.2 -> #DIV/0! | AG18: =IF(AE18>AF18,AE18,AF18) -> #DIV/0!
A19: 10 | B19: =+'PERIODO 01'!B19 -> 0 | M19: =IF(ISBLANK(C19),"",IF(C19>D19,C19,D19)) | N19: =IF(ISBLANK(E19)," ",IF(E19>F19,E19,F19)) | O19: =IF(ISBLANK(G19),"",IF(G19>H19,G19,H19)) | P19: =IF(ISBLANK(I19),"",IF(I19>J19,I19,J19)) | Q19: =IF(ISBLANK(K19),"",IF(K19>L19,K19,L19)) | R19: =AVERAGE(M19:Q19) -> #DIV/0! | X19: =AVERAGE(S19:W19) -> #DIV/0! | AD19: =AVERAGE(Y19:AC19) -> #DIV/0! | AE19: =R19*0.5+X19*0.3+AD19*0.2 -> #DIV/0! | AG19: =IF(AE19>AF19,AE19,AF19) -> #DIV/0!
A20: 11 | B20: =+'PERIODO 01'!B20 -> 0 | M20: =IF(ISBLANK(C20),"",IF(C20>D20,C20,D20)) | N20: =IF(ISBLANK(E20)," ",IF(E20>F20,E20,F20)) | O20: =IF(ISBLANK(G20),"",IF(G20>H20,G20,H20)) | P20: =IF(ISBLANK(I20),"",IF(I20>J20,I20,J20)) | Q20: =IF(ISBLANK(K20),"",IF(K20>L20,K20,L20)) | R20: =AVERAGE(M20:Q20) -> #DIV/0! | X20: =AVERAGE(S20:W20) -> #DIV/0! | AD20: =AVERAGE(Y20:AC20) -> #DIV/0! | AE20: =R20*0.5+X20*0.3+AD20*0.2 -> #DIV/0! | AG20: =IF(AE20>AF20,AE20,AF20) -> #DIV/0!
A21: 12 | B21: =+'PERIODO 01'!B21 -> 0 | M21: =IF(ISBLANK(C21),"",IF(C21>D21,C21,D21)) | N21: =IF(ISBLANK(E21)," ",IF(E21>F21,E21,F21)) | O21: =IF(ISBLANK(G21),"",IF(G21>H21,G21,H21)) | P21: =IF(ISBLANK(I21),"",IF(I21>J21,I21,J21)) | Q21: =IF(ISBLANK(K21),"",IF(K21>L21,K21,L21)) | R21: =AVERAGE(M21:Q21) -> #DIV/0! | X21: =AVERAGE(S21:W21) -> #DIV/0! | AD21: =AVERAGE(Y21:AC21) -> #DIV/0! | AE21: =R21*0.5+X21*0.3+AD21*0.2 -> #DIV/0! | AG21: =IF(AE21>AF21,AE21,AF21) -> #DIV/0!
... A49: 40 | B49: =+'PERIODO 01'!B49 -> 0 | M49: =IF(ISBLANK(C49),"",IF(C49>D49,C49,D49)) | N49: =IF(ISBLANK(E49)," ",IF(E49>F49,E49,F49)) | O49: =IF(ISBLANK(G49),"",IF(G49>H49,G49,H49)) | P49: =IF(ISBLANK(I49),"",IF(I49>J49,I49,J49)) | Q49: =IF(ISBLANK(K49),"",IF(K49>L49,K49,L49)) | R49: =AVERAGE(M49:Q49) -> #DIV/0! | X49: =AVERAGE(S49:W49) -> #DIV/0! | AD49: =AVERAGE(Y49:AC49) -> #DIV/0! | AE49: =R49*0.5+X49*0.3+AD49*0.2 -> #DIV/0! | AG49: =IF(AE49>AF49,AE49,AF49) -> #DIV/0!

Sheet PERIODO 03
C1: COGNITIVAS | S1: PROCEDIMENTALES | Y1: AXIOLÓGICAS | AE1: NOTA PARCIAL | AF1: ASPE | AG1: NOT FINAL PERIODO
C2: Nº ACT | D2: Descripción de la Actividad realizada para cada Nota | S2: Nº ACT | T2: Descripción de la Actividad realizada para cada Nota | Y2: Nº ACT | Z2: Descripción de la Actividad realizada para cada Nota
A3: =CONCATENATE(INICIO!B7," ",INICIO!C7) -> SEDE: | C3: NOTA1 | S3: NOTA1 | Y3: NOTA1
A4: =CONCATENATE(INICIO!D7," ",INICIO!E7) -> DOCENTE: | C4: NOTA 2 | S4: NOTA2 | Y4: NOTA2
A5: =CONCATENATE(INICIO!B8," ",INICIO!C8) -> ASIGNATURA: | C5: NOTA 3 | S5: NOTA3 | Y5: NOTA3
A6: =CONCATENATE(INICIO!D8,INICIO!E8," ",INICIO!F8,INICIO!G8) -> GRADO: GRUPO: | C6: NOTA 4 | S6: NOTA4 | Y6: NOTA4
A7: Periodo 03 | C7: NOTA 5 | S7: NOTA5 | Y7: NOTA5
C8: NOTA 1 | E8: NOTA 2 | G8: NOTA 3 | I8: NOTA 4 | K8: NOTA 5 | R8: N.P | S8: NOTA 1 | T8: NOTA 2 | U8: NOTA 3 | V8: NOTA 4 | W8: NOTA 5 | X8: N.P | Y8: NOTA 1 | Z8: NOTA 2 | AA8: NOTA 3 | AB8: NOTA 4 | AC8: NOTA 5 | AD8: N.P
A9: NO | B9: ESTUDIANTE | C9: NI | D9: AC | E9: NI | F9: AC | G9: NI | H9: AC | I9: NI | J9: AC | K9: NI | L9: AC | M9: n1 | N9: n2 | O9: n3 | P9: n4 | Q9: n5
A10: 1 | B10: =+'PERIODO 01'!B10 -> 0 | M10: =IF(ISBLANK(C10),"",IF(C10>D10,C10,D10)) | N10: =IF(ISBLANK(E10)," ",IF(E10>F10,E10,F10)) | O10: =IF(ISBLANK(G10),"",IF(G10>H10,G10,H10)) | P10: =IF(ISBLANK(I10),"",IF(I10>J10,I10,J10)) | Q10: =IF(ISBLANK(K10),"",IF(K10>L10,K10,L10)) | R10: =AVERAGE(M10:Q10) -> #DIV/0! | X10: =AVERAGE(S10:W10) -> #DIV/0! | AD10: =AVERAGE(Y10:AC10) -> #DIV/0! | AE10: =R10*0.5+X10*0.3+AD10*0.2 -> #DIV/0! | AG10: =IF(AE10>AF10,AE10,AF10) -> #DIV/0!
A11: 2 | B11: =+'PERIODO 01'!B11 -> 0 | M11: =IF(ISBLANK(C11),"",IF(C11>D11,C11,D11)) | N11: =IF(ISBLANK(E11)," ",IF(E11>F11,E11,F11)) | O11: =IF(ISBLANK(G11),"",IF(G11>H11,G11,H11)) | P11: =IF(ISBLANK(I11),"",IF(I11>J11,I11,J11)) | Q11: =IF(ISBLANK(K11),"",IF(K11>L11,K11,L11)) | R11: =AVERAGE(M11:Q11) -> #DIV/0! | X11: =AVERAGE(S11:W11) -> #DIV/0! | AD11: =AVERAGE(Y11:AC11) -> #DIV/0! | AE11: =R11*0.5+X11*0.3+AD11*0.2 -> #DIV/0! | AG11: =IF(AE11>AF11,AE11,AF11) -> #DIV/0!
A12: 3 | B12: =+'PERIODO 01'!B12 -> 0 | M12: =IF(ISBLANK(C12),"",IF(C12>D12,C12,D12)) | N12: =IF(ISBLANK(E12)," ",IF(E12>F12,E12,F12)) | O12: =IF(ISBLANK(G12),"",IF(G12>H12,G12,H12)) | P12: =IF(ISBLANK(I12),"",IF(I12>J12,I12,J12)) | Q12: =IF(ISBLANK(K12),"",IF(K12>L12,K12,L12)) | R12: =AVERAGE(M12:Q12) -> #DIV/0! | X12: =AVERAGE(S12:W12) -> #DIV/0! | AD12: =AVERAGE(Y12:AC12) -> #DIV/0! | AE12: =R12*0.5+X12*0.3+AD12*0.2 -> #DIV/0! | AG12: =IF(AE12>AF12,AE12,AF12) -> #DIV/0!
A13: 4 | B13: =+'PERIODO 01'!B13 -> 0 | M13: =IF(ISBLANK(C13),"",IF(C13>D13,C13,D13)) | N13: =IF(ISBLANK(E13)," ",IF(E13>F13,E13,F13)) | O13: =IF(ISBLANK(G13),"",IF(G13>H13,G13,H13)) | P13: =IF(ISBLANK(I13),"",IF(I13>J13,I13,J13)) | Q13: =IF(ISBLANK(K13),"",IF(K13>L13,K13,L13)) | R13: =AVERAGE(M13:Q13) -> #DIV/0! | X13: =AVERAGE(S13:W13) -> #DIV/0! | AD13: =AVERAGE(Y13:AC13) -> #DIV/0! | AE13: =R13*0.5+X13*0.3+AD13*0.2 -> #DIV/0! | AG13: =IF(AE13>AF13,AE13,AF13) -> #DIV/0!
A14: 5 | B14: =+'PERIODO 01'!B14 -> 0 | M14: =IF(ISBLANK(C14),"",IF(C14>D14,C14,D14)) | N14: =IF(ISBLANK(E14)," ",IF(E14>F14,E14,F14)) | O14: =IF(ISBLANK(G14),"",IF(G14>H14,G14,H14)) | P14: =IF(ISBLANK(I14),"",IF(I14>J14,I14,J14)) | Q14: =IF(ISBLANK(K14),"",IF(K14>L14,K14,L14)) | R14: =AVERAGE(M14:Q14) -> #DIV/0! | X14: =AVERAGE(S14:W14) -> #DIV/0! | AD14: =AVERAGE(Y14:AC14) -> #DIV/0! | AE14: =R14*0.5+X14*0.3+AD14*0.2 -> #DIV/0! | AG14: =IF(AE14>AF14,AE14,AF14) -> #DIV/0!
A15: 6 | B15: =+'PERIODO 01'!B15 -> 0 | M15: =IF(ISBLANK(C15),"",IF(C15>D15,C15,D15)) | N15: =IF(ISBLANK(E15)," ",IF(E15>F15,E15,F15)) | O15: =IF(ISBLANK(G15),"",IF(G15>H15,G15,H15)) | P15: =IF(ISBLANK(I15),"",IF(I15>J15,I15,J15)) | Q15: =IF(ISBLANK(K15),"",IF(K15>L15,K15,L15)) | R15: =AVERAGE(M15:Q15) -> #DIV/0! | X15: =AVERAGE(S15:W15) -> #DIV/0! | AD15: =AVERAGE(Y15:AC15) -> #DIV/0! | AE15: =R15*0.5+X15*0.3+AD15*0.2 -> #DIV/0! | AG15: =IF(AE15>AF15,AE15,AF15) -> #DIV/0!
A16: 7 | B16: =+'PERIODO 01'!B16 -> 0 | M16: =IF(ISBLANK(C16),"",IF(C16>D16,C16,D16)) | N16: =IF(ISBLANK(E16)," ",IF(E16>F16,E16,F16)) | O16: =IF(ISBLANK(G16),"",IF(G16>H16,G16,H16)) | P16: =IF(ISBLANK(I16),"",IF(I16>J16,I16,J16)) | Q16: =IF(ISBLANK(K16),"",IF(K16>L16,K16,L16)) | R16: =AVERAGE(M16:Q16) -> #DIV/0! | X16: =AVERAGE(S16:W16) -> #DIV/0! | AD16: =AVERAGE(Y16:AC16) -> #DIV/0! | AE16: =R16*0.5+X16*0.3+AD16*0.2 -> #DIV/0! | AG16: =IF(AE16>AF16,AE16,AF16) -> #DIV/0!
A17: 8 | B17: =+'PERIODO 01'!B17 -> 0 | M17: =IF(ISBLANK(C17),"",IF(C17>D17,C17,D17)) | N17: =IF(ISBLANK(E17)," ",IF(E17>F17,E17,F17)) | O17: =IF(ISBLANK(G17),"",IF(G17>H17,G17,H17)) | P17: =IF(ISBLANK(I17),"",IF(I17>J17,I17,J17)) | Q17: =IF(ISBLANK(K17),"",IF(K17>L17,K17,L17)) | R17: =AVERAGE(M17:Q17) -> #DIV/0! | X17: =AVERAGE(S17:W17) -> #DIV/0! | AD17: =AVERAGE(Y17:AC17) -> #DIV/0! | AE17: =R17*0.5+X17*0.3+AD17*0.2 -> #DIV/0! | AG17: =IF(AE17>AF17,AE17,AF17) -> #DIV/0!
A18: 9 | B18: =+'PERIODO 01'!B18 -> 0 | M18: =IF(ISBLANK(C18),"",IF(C18>D18,C18,D18)) | N18: =IF(ISBLANK(E18)," ",IF(E18>F18,E18,F18)) | O18: =IF(ISBLANK(G18),"",IF(G18>H18,G18,H18)) | P18: =IF(ISBLANK(I18),"",IF(I18>J18,I18,J18)) | Q18: =IF(ISBLANK(K18),"",IF(K18>L18,K18,L18)) | R18: =AVERAGE(M18:Q18) -> #DIV/0! | X18: =AVERAGE(S18:W18) -> #DIV/0! | AD18: =AVERAGE(Y18:AC18) -> #DIV/0! | AE18: =R18*0.5+X18*0.3+AD18*0.2 -> #DIV/0! | AG18: =IF(AE18>AF18,AE18,AF18) -> #DIV/0!
A19: 10 | B19: =+'PERIODO 01'!B19 -> 0 | M19: =IF(ISBLANK(C19),"",IF(C19>D19,C19,D19)) | N19: =IF(ISBLANK(E19)," ",IF(E19>F19,E19,F19)) | O19: =IF(ISBLANK(G19),"",IF(G19>H19,G19,H19)) | P19: =IF(ISBLANK(I19),"",IF(I19>J19,I19,J19)) | Q19: =IF(ISBLANK(K19),"",IF(K19>L19,K19,L19)) | R19: =AVERAGE(M19:Q19) -> #DIV/0! | X19: =AVERAGE(S19:W19) -> #DIV/0! | AD19: =AVERAGE(Y19:AC19) -> #DIV/0! | AE19: =R19*0.5+X19*0.3+AD19*0.2 -> #DIV/0! | AG19: =IF(AE19>AF19,AE19,AF19) -> #DIV/0!
A20: 11 | B20: =+'PERIODO 01'!B20 -> 0 | M20: =IF(ISBLANK(C20),"",IF(C20>D20,C20,D20)) | N20: =IF(ISBLANK(E20)," ",IF(E20>F20,E20,F20)) | O20: =IF(ISBLANK(G20),"",IF(G20>H20,G20,H20)) | P20: =IF(ISBLANK(I20),"",IF(I20>J20,I20,J20)) | Q20: =IF(ISBLANK(K20),"",IF(K20>L20,K20,L20)) | R20: =AVERAGE(M20:Q20) -> #DIV/0! | X20: =AVERAGE(S20:W20) -> #DIV/0! | AD20: =AVERAGE(Y20:AC20) -> #DIV/0! | AE20: =R20*0.5+X20*0.3+AD20*0.2 -> #DIV/0! | AG20: =IF(AE20>AF20,AE20,AF20) -> #DIV/0!
A21: 12 | B21: =+'PERIODO 01'!B21 -> 0 | M21: =IF(ISBLANK(C21),"",IF(C21>D21,C21,D21)) | N21: =IF(ISBLANK(E21)," ",IF(E21>F21,E21,F21)) | O21: =IF(ISBLANK(G21),"",IF(G21>H21,G21,H21)) | P21: =IF(ISBLANK(I21),"",IF(I21>J21,I21,J21)) | Q21: =IF(ISBLANK(K21),"",IF(K21>L21,K21,L21)) | R21: =AVERAGE(M21:Q21) -> #DIV/0! | X21: =AVERAGE(S21:W21) -> #DIV/0! | AD21: =AVERAGE(Y21:AC21) -> #DIV/0! | AE21: =R21*0.5+X21*0.3+AD21*0.2 -> #DIV/0! | AG21: =IF(AE21>AF21,AE21,AF21) -> #DIV/0!
... A49: 40 | B49: =+'PERIODO 01'!B49 -> 0 | M49: =IF(ISBLANK(C49),"",IF(C49>D49,C49,D49)) | N49: =IF(ISBLANK(E49)," ",IF(E49>F49,E49,F49)) | O49: =IF(ISBLANK(G49),"",IF(G49>H49,G49,H49)) | P49: =IF(ISBLANK(I49),"",IF(I49>J49,I49,J49)) | Q49: =IF(ISBLANK(K49),"",IF(K49>L49,K49,L49)) | R49: =AVERAGE(M49:Q49) -> #DIV/0! | X49: =AVERAGE(S49:W49) -> #DIV/0! | AD49: =AVERAGE(Y49:AC49) -> #DIV/0! | AE49: =R49*0.5+X49*0.3+AD49*0.2 -> #DIV/0! | AG49: =IF(AE49>AF49,AE49,AF49) -> #DIV/0!

Sheet FINAL
A5: INFORME DE NOTAS FINALES
A6: Nº | B6: ESTUDIANTE | C6: PERIODO 01 | D6: PERIODO 02 | E6: PERIODO 03 | F6: FINAL PARCIAL | G6: ASPE FINAL | H6: FINAL DEL AÑO | I6: 1 PERIODO | J6: 2 PERIODO | K6: 3 PERIODO | L6: 4 PERIODO | M6: FINAL | N6: 1 PERIODO | O6: 2 PERIODO | P6: 3 PERIODO | Q6: 4 PERIODO | R6: FINAL
A9: 1 | B9: =+'PERIODO 03'!B10 -> 0 | C9: =+'PERIODO 01'!AG10 -> #DIV/0! | D9: =+'PERIODO 02'!AG10 -> #DIV/0! | E9: =+'PERIODO 03'!AG10 -> #DIV/0! | F9: =(C9*34%)+(D9*33%)+(E9*33%) -> #DIV/0! | H9: =IF(F9>G9,F9,G9) -> #DIV/0! | I9: =IF(C9<3,"BAJO",IF(C9<4,"BASICO",IF(C9<4.5,"ALTO","SUPERIOR"))) -> #DIV/0! | J9: =IF(D9<3,"BAJO",IF(D9<4,"BASICO",IF(D9<4.5,"ALTO","SUPERIOR"))) -> #DIV/0! | K9: =IF(E9<3,"BAJO",IF(E9<4,"BASICO",IF(E9<4.5,"ALTO","SUPERIOR"))) -> #DIV/0! | L9: =IF(#REF!<3,"BAJO",IF(#REF!<4,"BASICO",IF(#REF!<4.5,"ALTO","SUPERIOR"))) -> #REF! | M9: =IF(H9<3,"BAJO",IF(H9<4,"BASICO",IF(H9<4.5,"ALTO","SUPERIOR"))) -> #DIV/0! | N9: BAJO | O9: BAJO | P9: BAJO | Q9: BAJO | R9: BAJO
A10: 2 | B10: =+'PERIODO 03'!B11 -> 0 | C10: =+'PERIODO 01'!AG11 -> #DIV/0! | D10: =+'PERIODO 02'!AG11 -> #DIV/0! | E10: =+'PERIODO 03'!AG11 -> #DIV/0! | F10: =(C10*34%)+(D10*33%)+(E10*33%) -> #DIV/0! | H10: =IF(F10>G10,F10,G10) -> #DIV/0! | I10: =IF(C10<3,"BAJO",IF(C10<4,"BASICO",IF(C10<4.5,"ALTO","SUPERIOR"))) -> #DIV/0! | J10: =IF(D10<3,"BAJO",IF(D10<4,"BASICO",IF(D10<4.5,"ALTO","SUPERIOR"))) -> #DIV/0! | K10: =IF(E10<3,"BAJO",IF(E10<4,"BASICO",IF(E10<4.5,"ALTO","SUPERIOR"))) -> #DIV/0! | L10: =IF(#REF!<3,"BAJO",IF(#REF!<4,"BASICO",IF(#REF!<4.5,"ALTO","SUPERIOR"))) -> #REF! | M10: =IF(H10<3,"BAJO",IF(H10<4,"BASICO",IF(H10<4.5,"ALTO","SUPERIOR"))) -> #DIV/0! | N10: =COUNTIF(I9:I48,"BAJO") -> 0 | O10: =COUNTIF(J9:J48,"BAJO") -> 0 | P10: =COUNTIF(K9:K48,"BAJO") -> 0 | Q10: =COUNTIF(L9:L48,"BAJO") -> 0 | R10: =COUNTIF(M9:M48,"BAJO") -> 0
A11: 3 | B11: =+'PERIODO 03'!B12 -> 0 | C11: =+'PERIODO 01'!AG12 -> #DIV/0! | D11: =+'PERIODO 02'!AG12 -> #DIV/0! | E11: =+'PERIODO 03'!AG12 -> #DIV/0! | F11: =(C11*34%)+(D11*33%)+(E11*33%) -> #DIV/0! | H11: =IF(F11>G11,F11,G11) -> #DIV/0! | I11: =IF(C11<3,"BAJO",IF(C11<4,"BASICO",IF(C11<4.5,"ALTO","SUPERIOR"))) -> #DIV/0! | J11: =IF(D11<3,"BAJO",IF(D11<4,"BASICO",IF(D11<4.5,"ALTO","SUPERIOR"))) -> #DIV/0! | K11: =IF(E11<3,"BAJO",IF(E11<4,"BASICO",IF(E11<4.5,"ALTO","SUPERIOR"))) -> #DIV/0! | L11: =IF(#REF!<3,"BAJO",IF(#REF!<4,"BASICO",IF(#REF!<4.5,"ALTO","SUPERIOR"))) -> #REF! | M11: =IF(H11<3,"BAJO",IF(H11<4,"BASICO",IF(H11<4.5,"ALTO","SUPERIOR"))) -> #DIV/0! | N11: BASICO | O11: BASICO | P11: BASICO | Q11: BASICO | R11: BASICO
A12: 4 | B12: =+'PERIODO 03'!B13 -> 0 | C12: =+'PERIODO 01'!AG13 -> #DIV/0! | D12: =+'PERIODO 02'!AG13 -> #DIV/0! | E12: =+'PERIODO 03'!AG13 -> #DIV/0! | F12: =(C12*34%)+(D12*33%)+(E12*33%) -> #DIV/0! | H12: =IF(F12>G12,F12,G12) -> #DIV/0! | I12: =IF(C12<3,"BAJO",IF(C12<4,"BASICO",IF(C12<4.5,"ALTO","SUPERIOR"))) -> #DIV/0! | J12: =IF(D12<3,"BAJO",IF(D12<4,"BASICO",IF(D12<4.5,"ALTO","SUPERIOR"))) -> #DIV/0! | K12: =IF(E12<3,"BAJO",IF(E12<4,"BASICO",IF(E12<4.5,"ALTO","SUPERIOR"))) -> #DIV/0! | L12: =IF(#REF!<3,"BAJO",IF(#REF!<4,"BASICO",IF(#REF!<4.5,"ALTO","SUPERIOR"))) -> #REF! | M12: =IF(H12<3,"BAJO",IF(H12<4,"BASICO",IF(H12<4.5,"ALTO","SUPERIOR"))) -> #DIV/0! | N12: =COUNTIF(I9:I48,"BASICO") -> 0 | O12: =COUNTIF(J9:J48,"BASICO") -> 0 | P12: =COUNTIF(K9:K48,"BASICO") -> 0 | Q12: =COUNTIF(L9:L48,"BASICO") -> 0 | R12: =COUNTIF(M9:M48,"BASICO") -> 0
A13: 5 | B13: =+'PERIODO 03'!B14 -> 0 | C13: =+'PERIODO 01'!AG14 -> #DIV/0! | D13: =+'PERIODO 02'!AG14 -> #DIV/0! | E13: =+'PERIODO 03'!AG14 -> #DIV/0! | F13: =(C13*34%)+(D13*33%)+(E13*33%) -> #DIV/0! | H13: =IF(F13>G13,F13,G13) -> #DIV/0! | I13: =IF(C13<3,"BAJO",IF(C13<4,"BASICO",IF(C13<4.5,"ALTO","SUPERIOR"))) -> #DIV/0! | J13: =IF(D13<3,"BAJO",IF(D13<4,"BASICO",IF(D13<4.5,"ALTO","SUPERIOR"))) -> #DIV/0! | K13: =IF(E13<3,"BAJO",IF(E13<4,"BASICO",IF(E13<4.5,"ALTO","SUPERIOR"))) -> #DIV/0! | L13: =IF(#REF!<3,"BAJO",IF(#REF!<4,"BASICO",IF(#REF!<4.5,"ALTO","SUPERIOR"))) -> #REF! | M13: =IF(H13<3,"BAJO",IF(H13<4,"BASICO",IF(H13<4.5,"ALTO","SUPERIOR"))) -> #DIV/0! | N13: ALTO | O13: ALTO | P13: ALTO | Q13: ALTO | R13: ALTO
A14: 6 | B14: =+'PERIODO 03'!B15 -> 0 | C14: =+'PERIODO 01'!AG15 -> #DIV/0! | D14: =+'PERIODO 02'!AG15 -> #DIV/0! | E14: =+'PERIODO 03'!AG15 -> #DIV/0! | F14: =(C14*34%)+(D14*33%)+(E14*33%) -> #DIV/0! | H14: =IF(F14>G14,F14,G14) -> #DIV/0! | I14: =IF(C14<3,"BAJO",IF(C14<4,"BASICO",IF(C14<4.5,"ALTO","SUPERIOR"))) -> #DIV/0! | J14: =IF(D14<3,"BAJO",IF(D14<4,"BASICO",IF(D14<4.5,"ALTO","SUPERIOR"))) -> #DIV/0! | K14: =IF(E14<3,"BAJO",IF(E14<4,"BASICO",IF(E14<4.5,"ALTO","SUPERIOR"))) -> #DIV/0! | L14: =IF(#REF!<3,"BAJO",IF(#REF!<4,"BASICO",IF(#REF!<4.5,"ALTO","SUPERIOR"))) -> #REF! | M14: =IF(H14<3,"BAJO",IF(H14<4,"BASICO",IF(H14<4.5,"ALTO","SUPERIOR"))) -> #DIV/0! | N14: =COUNTIF(I9:I48,"ALTO") -> 0 | O14: =COUNTIF(J9:J48,"ALTO") -> 0 | P14: =COUNTIF(K9:K48,"ALTO") -> 0 | Q14: =COUNTIF(L9:L48,"ALTO") -> 0 | R14: =COUNTIF(M9:M48,"ALTO") -> 0
A15: 7 | B15: =+'PERIODO 03'!B16 -> 0 | C15: =+'PERIODO 01'!AG16 -> #DIV/0! | D15: =+'PERIODO 02'!AG16 -> #DIV/0! | E15: =+'PERIODO 03'!AG16 -> #DIV/0! | F15: =(C15*34%)+(D15*33%)+(E15*33%) -> #DIV/0! | H15: =IF(F15>G15,F15,G15) -> #DIV/0! | I15: =IF(C15<3,"BAJO",IF(C15<4,"BASICO",IF(C15<4.5,"ALTO","SUPERIOR"))) -> #DIV/0! | J15: =IF(D15<3,"BAJO",IF(D15<4,"BASICO",IF(D15<4.5,"ALTO","SUPERIOR"))) -> #DIV/0! | K15: =IF(E15<3,"BAJO",IF(E15<4,"BASICO",IF(E15<4.5,"ALTO","SUPERIOR"))) -> #DIV/0! | L15: =IF(#REF!<3,"BAJO",IF(#REF!<4,"BASICO",IF(#REF!<4.5,"ALTO","SUPERIOR"))) -> #REF! | M15: =IF(H15<3,"BAJO",IF(H15<4,"BASICO",IF(H15<4.5,"ALTO","SUPERIOR"))) -> #DIV/0! | N15: SUPERIOR | O15: SUPERIOR | P15: SUPERIOR | Q15: SUPERIOR | R15: SUPERIOR
A16: 8 | B16: =+'PERIODO 03'!B17 -> 0 | C16: =+'PERIODO 01'!AG17 -> #DIV/0! | D16: =+'PERIODO 02'!AG17 -> #DIV/0! | E16: =+'PERIODO 03'!AG17 -> #DIV/0! | F16: =(C16*34%)+(D16*33%)+(E16*33%) -> #DIV/0! | H16: =IF(F16>G16,F16,G16) -> #DIV/0! | I16: =IF(C16<3,"BAJO",IF(C16<4,"BASICO",IF(C16<4.5,"ALTO","SUPERIOR"))) -> #DIV/0! | J16: =IF(D16<3,"BAJO",IF(D16<4,"BASICO",IF(D16<4.5,"ALTO","SUPERIOR"))) -> #DIV/0! | K16: =IF(E16<3,"BAJO",IF(E16<4,"BASICO",IF(E16<4.5,"ALTO","SUPERIOR"))) -> #DIV/0! | L16: =IF(#REF!<3,"BAJO",IF(#REF!<4,"BASICO",IF(#REF!<4.5,"ALTO","SUPERIOR"))) -> #REF! | M16: =IF(H16<3,"BAJO",IF(H16<4,"BASICO",IF(H16<4.5,"ALTO","SUPERIOR"))) -> #DIV/0! | N16: =COUNTIF(I9:I48,"SUPERIOR") -> 0 | O16: =COUNTIF(J9:J48,"SUPERIOR") -> 0 | P16: =COUNTIF(K9:K48,"SUPERIOR") -> 0 | Q16: =COUNTIF(L9:L48,"SUPERIOR") -> 0 | R16: =COUNTIF(M9:M48,"SUPERIOR") -> 0
A17: 9 | B17: =+'PERIODO 03'!B18 -> 0 | C17: =+'PERIODO 01'!AG18 -> #DIV/0! | D17: =+'PERIODO 02'!AG18 -> #DIV/0! | E17: =+'PERIODO 03'!AG18 -> #DIV/0! | F17: =(C17*34%)+(D17*33%)+(E17*33%) -> #DIV/0! | H17: =IF(F17>G17,F17,G17) -> #DIV/0! | I17: =IF(C17<3,"BAJO",IF(C17<4,"BASICO",IF(C17<4.5,"ALTO","SUPERIOR"))) -> #DIV/0! | J17: =IF(D17<3,"BAJO",IF(D17<4,"BASICO",IF(D17<4.5,"ALTO","SUPERIOR"))) -> #DIV/0! | K17: =IF(E17<3,"BAJO",IF(E17<4,"BASICO",IF(E17<4.5,"ALTO","SUPERIOR"))) -> #DIV/0! | L17: =IF(#REF!<3,"BAJO",IF(#REF!<4,"BASICO",IF(#REF!<4.5,"ALTO","SUPERIOR"))) -> #REF! | M17: =IF(H17<3,"BAJO",IF(H17<4,"BASICO",IF(H17<4.5,"ALTO","SUPERIOR"))) -> #DIV/0!
A18: 10 | B18: =+'PERIODO 03'!B19 -> 0 | C18: =+'PERIODO 01'!AG19 -> #DIV/0! | D18: =+'PERIODO 02'!AG19 -> #DIV/0! | E18: =+'PERIODO 03'!AG19 -> #DIV/0! | F18: =(C18*34%)+(D18*33%)+(E18*33%) -> #DIV/0! | H18: =IF(F18>G18,F18,G18) -> #DIV/0! | I18: =IF(C18<3,"BAJO",IF(C18<4,"BASICO",IF(C18<4.5,"ALTO","SUPERIOR"))) -> #DIV/0! | J18: =IF(D18<3,"BAJO",IF(D18<4,"BASICO",IF(D18<4.5,"ALTO","SUPERIOR"))) -> #DIV/0! | K18: =IF(E18<3,"BAJO",IF(E18<4,"BASICO",IF(E18<4.5,"ALTO","SUPERIOR"))) -> #DIV/0! | L18: =IF(#REF!<3,"BAJO",IF(#REF!<4,"BASICO",IF(#REF!<4.5,"ALTO","SUPERIOR"))) -> #REF! | M18: =IF(H18<3,"BAJO",IF(H18<4,"BASICO",IF(H18<4.5,"ALTO","SUPERIOR"))) -> #DIV/0!
A19: 11 | B19: =+'PERIODO 03'!B20 -> 0 | C19: =+'PERIODO 01'!AG20 -> #DIV/0! | D19: =+'PERIODO 02'!AG20 -> #DIV/0! | E19: =+'PERIODO 03'!AG20 -> #DIV/0! | F19: =(C19*34%)+(D19*33%)+(E19*33%) -> #DIV/0! | H19: =IF(F19>G19,F19,G19) -> #DIV/0! | I19: =IF(C19<3,"BAJO",IF(C19<4,"BASICO",IF(C19<4.5,"ALTO","SUPERIOR"))) -> #DIV/0! | J19: =IF(D19<3,"BAJO",IF(D19<4,"BASICO",IF(D19<4.5,"ALTO","SUPERIOR"))) -> #DIV/0! | K19: =IF(E19<3,"BAJO",IF(E19<4,"BASICO",IF(E19<4.5,"ALTO","SUPERIOR"))) -> #DIV/0! | L19: =IF(#REF!<3,"BAJO",IF(#REF!<4,"BASICO",IF(#REF!<4.5,"ALTO","SUPERIOR"))) -> #REF! | M19: =IF(H19<3,"BAJO",IF(H19<4,"BASICO",IF(H19<4.5,"ALTO","SUPERIOR"))) -> #DIV/0!
A20: 12 | B20: =+'PERIODO 03'!B21 -> 0 | C20: =+'PERIODO 01'!AG21 -> #DIV/0! | D20: =+'PERIODO 02'!AG21 -> #DIV/0! | E20: =+'PERIODO 03'!AG21 -> #DIV/0! | F20: =(C20*34%)+(D20*33%)+(E20*33%) -> #DIV/0! | H20: =IF(F20>G20,F20,G20) -> #DIV/0! | I20: =IF(C20<3,"BAJO",IF(C20<4,"BASICO",IF(C20<4.5,"ALTO","SUPERIOR"))) -> #DIV/0! | J20: =IF(D20<3,"BAJO",IF(D20<4,"BASICO",IF(D20<4.5,"ALTO","SUPERIOR"))) -> #DIV/0! | K20: =IF(E20<3,"BAJO",IF(E20<4,"BASICO",IF(E20<4.5,"ALTO","SUPERIOR"))) -> #DIV/0! | L20: =IF(#REF!<3,"BAJO",IF(#REF!<4,"BASICO",IF(#REF!<4.5,"ALTO","SUPERIOR"))) -> #REF! | M20: =IF(H20<3,"BAJO",IF(H20<4,"BASICO",IF(H20<4.5,"ALTO","SUPERIOR"))) -> #DIV/0!
A21: 13 | B21: =+'PERIODO 03'!B22 -> 0 | C21: =+'PERIODO 01'!AG22 -> #DIV/0! | D21: =+'PERIODO 02'!AG22 -> #DIV/0! | E21: =+'PERIODO 03'!AG22 -> #DIV/0! | F21: =(C21*34%)+(D21*33%)+(E21*33%) -> #DIV/0! | H21: =IF(F21>G21,F21,G21) -> #DIV/0! | I21: =IF(C21<3,"BAJO",IF(C21<4,"BASICO",IF(C21<4.5,"ALTO","SUPERIOR"))) -> #DIV/0! | J21: =IF(D21<3,"BAJO",IF(D21<4,"BASICO",IF(D21<4.5,"ALTO","SUPERIOR"))) -> #DIV/0! | K21: =IF(E21<3,"BAJO",IF(E21<4,"BASICO",IF(E21<4.5,"ALTO","SUPERIOR"))) -> #DIV/0! | L21: =IF(#REF!<3,"BAJO",IF(#REF!<4,"BASICO",IF(#REF!<4.5,"ALTO","SUPERIOR"))) -> #REF! | M21: =IF(H21<3,"BAJO",IF(H21<4,"BASICO",IF(H21<4.5,"ALTO","SUPERIOR"))) -> #DIV/0!
A22: 14 | B22: =+'PERIODO 03'!B23 -> 0 | C22: =+'PERIODO 01'!AG23 -> #DIV/0! | D22: =+'PERIODO 02'!AG23 -> #DIV/0! | E22: =+'PERIODO 03'!AG23 -> #DIV/0! | F22: =(C22*34%)+(D22*33%)+(E22*33%) -> #DIV/0! | H22: =IF(F22>G22,F22,G22) -> #DIV/0! | I22: =IF(C22<3,"BAJO",IF(C22<4,"BASICO",IF(C22<4.5,"ALTO","SUPERIOR"))) -> #DIV/0! | J22: =IF(D22<3,"BAJO",IF(D22<4,"BASICO",IF(D22<4.5,"ALTO","SUPERIOR"))) -> #DIV/0! | K22: =IF(E22<3,"BAJO",IF(E22<4,"BASICO",IF(E22<4.5,"ALTO","SUPERIOR"))) -> #DIV/0! | L22: =IF(#REF!<3,"BAJO",IF(#REF!<4,"BASICO",IF(#REF!<4.5,"ALTO","SUPERIOR"))) -> #REF! | M22: =IF(H22<3,"BAJO",IF(H22<4,"BASICO",IF(H22<4.5,"ALTO","SUPERIOR"))) -> #DIV/0!
A23: 15 | B23: =+'PERIODO 03'!B24 -> 0 | C23: =+'PERIODO 01'!AG24 -> #DIV/0! | D23: =+'PERIODO 02'!AG24 -> #DIV/0! | E23: =+'PERIODO 03'!AG24 -> #DIV/0! | F23: =(C23*34%)+(D23*33%)+(E23*33%) -> #DIV/0! | H23: =IF(F23>G23,F23,G23) -> #DIV/0! | I23: =IF(C23<3,"BAJO",IF(C23<4,"BASICO",IF(C23<4.5,"ALTO","SUPERIOR"))) -> #DIV/0! | J23: =IF(D23<3,"BAJO",IF(D23<4,"BASICO",IF(D23<4.5,"ALTO","SUPERIOR"))) -> #DIV/0! | K23: =IF(E23<3,"BAJO",IF(E23<4,"BASICO",IF(E23<4.5,"ALTO","SUPERIOR"))) -> #DIV/0! | L23: =IF(#REF!<3,"BAJO",IF(#REF!<4,"BASICO",IF(#REF!<4.5,"ALTO","SUPERIOR"))) -> #REF! | M23: =IF(H23<3,"BAJO",IF(H23<4,"BASICO",IF(H23<4.5,"ALTO","SUPERIOR"))) -> #DIV/0!
A24: 16 | B24: =+'PERIODO 03'!B25 -> 0 | C24: =+'PERIODO 01'!AG25 -> #DIV/0! | D24: =+'PERIODO 02'!AG25 -> #DIV/0! | E24: =+'PERIODO 03'!AG25 -> #DIV/0! | F24: =(C24*34%)+(D24*33%)+(E24*33%) -> #DIV/0! | H24: =IF(F24>G24,F24,G24) -> #DIV/0! | I24: =IF(C24<3,"BAJO",IF(C24<4,"BASICO",IF(C24<4.5,"ALTO","SUPERIOR"))) -> #DIV/0! | J24: =IF(D24<3,"BAJO",IF(D24<4,"BASICO",IF(D24<4.5,"ALTO","SUPERIOR"))) -> #DIV/0! | K24: =IF(E24<3,"BAJO",IF(E24<4,"BASICO",IF(E24<4.5,"ALTO","SUPERIOR"))) -> #DIV/0! | L24: =IF(#REF!<3,"BAJO",IF(#REF!<4,"BASICO",IF(#REF!<4.5,"ALTO","SUPERIOR"))) -> #REF! | M24: =IF(H24<3,"BAJO",IF(H24<4,"BASICO",IF(H24<4.5,"ALTO","SUPERIOR"))) -> #DIV/0!
A25: 17 | B25: =+'PERIODO 03'!B26 -> 0 | C25: =+'PERIODO 01'!AG26 -> #DIV/0! | D25: =+'PERIODO 02'!AG26 -> #DIV/0! | E25: =+'PERIODO 03'!AG26 -> #DIV/0! | F25: =(C25*34%)+(D25*33%)+(E25*33%) -> #DIV/0! | H25: =IF(F25>G25,F25,G25) -> #DIV/0! | I25: =IF(C25<3,"BAJO",IF(C25<4,"BASICO",IF(C25<4.5,"ALTO","SUPERIOR"))) -> #DIV/0! | J25: =IF(D25<3,"BAJO",IF(D25<4,"BASICO",IF(D25<4.5,"ALTO","SUPERIOR"))) -> #DIV/0! | K25: =IF(E25<3,"BAJO",IF(E25<4,"BASICO",IF(E25<4.5,"ALTO","SUPERIOR"))) -> #DIV/0! | L25: =IF(#REF!<3,"BAJO",IF(#REF!<4,"BASICO",IF(#REF!<4.5,"ALTO","SUPERIOR"))) -> #REF! | M25: =IF(H25<3,"BAJO",IF(H25<4,"BASICO",IF(H25<4.5,"ALTO","SUPERIOR"))) -> #DIV/0!
A26: 18 | B26: =+'PERIODO 03'!B27 -> 0 | C26: =+'PERIODO 01'!AG27 -> #DIV/0! | D26: =+'PERIODO 02'!AG27 -> #DIV/0! | E26: =+'PERIODO 03'!AG27 -> #DIV/0! | F26: =(C26*34%)+(D26*33%)+(E26*33%) -> #DIV/0! | H26: =IF(F26>G26,F26,G26) -> #DIV/0! | I26: =IF(C26<3,"BAJO",IF(C26<4,"BASICO",IF(C26<4.5,"ALTO","SUPERIOR"))) -> #DIV/0! | J26: =IF(D26<3,"BAJO",IF(D26<4,"BASICO",IF(D26<4.5,"ALTO","SUPERIOR"))) -> #DIV/0! | K26: =IF(E26<3,"BAJO",IF(E26<4,"BASICO",IF(E26<4.5,"ALTO","SUPERIOR"))) -> #DIV/0! | L26: =IF(#REF!<3,"BAJO",IF(#REF!<4,"BASICO",IF(#REF!<4.5,"ALTO","SUPERIOR"))) -> #REF! | M26: =IF(H26<3,"BAJO",IF(H26<4,"BASICO",IF(H26<4.5,"ALTO","SUPERIOR"))) -> #DIV/0!
A27: 19 | B27: =+'PERIODO 03'!B28 -> 0 | C27: =+'PERIODO 01'!AG28 -> #DIV/0! | D27: =+'PERIODO 02'!AG28 -> #DIV/0! | E27: =+'PERIODO 03'!AG28 -> #DIV/0! | F27: =(C27*34%)+(D27*33%)+(E27*33%) -> #DIV/0! | H27: =IF(F27>G27,F27,G27) -> #DIV/0! | I27: =IF(C27<3,"BAJO",IF(C27<4,"BASICO",IF(C27<4.5,"ALTO","SUPERIOR"))) -> #DIV/0! | J27: =IF(D27<3,"BAJO",IF(D27<4,"BASICO",IF(D27<4.5,"ALTO","SUPERIOR"))) -> #DIV/0! | K27: =IF(E27<3,"BAJO",IF(E27<4,"BASICO",IF(E27<4.5,"ALTO","SUPERIOR"))) -> #DIV/0! | L27: =IF(#REF!<3,"BAJO",IF(#REF!<4,"BASICO",IF(#REF!<4.5,"ALTO","SUPERIOR"))) -> #REF! | M27: =IF(H27<3,"BAJO",IF(H27<4,"BASICO",IF(H27<4.5,"ALTO","SUPERIOR"))) -> #DIV/0!
A28: 20 | B28: =+'PERIODO 03'!B29 -> 0 | C28: =+'PERIODO 01'!AG29 -> #DIV/0! | D28: =+'PERIODO 02'!AG29 -> #DIV/0! | E28: =+'PERIODO 03'!AG29 -> #DIV/0! | F28: =(C28*34%)+(D28*33%)+(E28*33%) -> #DIV/0! | H28: =IF(F28>G28,F28,G28) -> #DIV/0! | I28: =IF(C28<3,"BAJO",IF(C28<4,"BASICO",IF(C28<4.5,"ALTO","SUPERIOR"))) -> #DIV/0! | J28: =IF(D28<3,"BAJO",IF(D28<4,"BASICO",IF(D28<4.5,"ALTO","SUPERIOR"))) -> #DIV/0! | K28: =IF(E28<3,"BAJO",IF(E28<4,"BASICO",IF(E28<4.5,"ALTO","SUPERIOR"))) -> #DIV/0! | L28: =IF(#REF!<3,"BAJO",IF(#REF!<4,"BASICO",IF(#REF!<4.5,"ALTO","SUPERIOR"))) -> #REF! | M28: =IF(H28<3,"BAJO",IF(H28<4,"BASICO",IF(H28<4.5,"ALTO","SUPERIOR"))) -> #DIV/0!
... A48: 40 | B48: =+'PERIODO 03'!B49 -> 0 | C48: =+'PERIODO 01'!AG49 -> #DIV/0! | D48: =+'PERIODO 02'!AG49 -> #DIV/0! | E48: =+'PERIODO 03'!AG49 -> #DIV/0! | F48: =(C48*34%)+(D48*33%)+(E48*33%) -> #DIV/0! | H48: =IF(F48>G48,F48,G48) -> #DIV/0! | I48: =IF(C48<3,"BAJO",IF(C48<4,"BASICO",IF(C48<4.5,"ALTO","SUPERIOR"))) -> #DIV/0! | J48: =IF(D48<3,"BAJO",IF(D48<4,"BASICO",IF(D48<4.5,"ALTO","SUPERIOR"))) -> #DIV/0! | K48: =IF(E48<3,"BAJO",IF(E48<4,"BASICO",IF(E48<4.5,"ALTO","SUPERIOR"))) -> #DIV/0! | L48: =IF(#REF!<3,"BAJO",IF(#REF!<4,"BASICO",IF(#REF!<4.5,"ALTO","SUPERIOR"))) -> #REF! | M48: =IF(H48<3,"BAJO",IF(H48<4,"BASICO",IF(H48<4.5,"ALTO","SUPERIOR"))) -> #DIV/0!

Sheet ESTADISTICA
B1: NÚMERO DE ESTUDIANTES POR DESEMPEÑO
B3: PERIODOS
A4: DESEMPEÑOS | B4: PER. 01 | C4: PER. 02 | D4: PER. 03 | E4: FINAL
A5: BAJO | B5: =FINAL!N10 -> 0 | C5: =FINAL!O10 -> 0 | D5: =FINAL!P10 -> 0 | E5: =FINAL!R10 -> 0
A6: BASICO | B6: =FINAL!N12 -> 0 | C6: =FINAL!O12 -> 0 | D6: =FINAL!P12 -> 0 | E6: =FINAL!R12 -> 0
A7: ALTO | B7: =FINAL!N14 -> 0 | C7: =FINAL!O14 -> 0 | D7: =FINAL!P14 -> 0 | E7: =FINAL!R14 -> 0
A8: SUPERIOR | B8: =FINAL!N16 -> 0 | C8: =FINAL!O16 -> 0 | D8: =FINAL!P16 -> 0 | E8: =FINAL!R16 -> 0
B9: =SUM(B5:B8) -> 0 | C9: =SUM(C5:C8) -> 0 | D9: =SUM(D5:D8) -> 0 | E9: =SUM(E5:E8) -> 0

Sheet INFORMES
B9: Nº | C9: NOMBRE DEL ESTUDIANTE | D9: NOTA | E9: PERIODO | F9: DESEMPEÑO
B10: =FINAL!A9 -> 1 | C10: =FINAL!B9 -> 0 | D10: =FINAL!C9 -> #DIV/0! | E10: PERIODO 01 | F10: =IF(D10<2.95,"BAJO",IF(D10<4,"BASICO",IF(D10<4.5,"ALTO","SUPERIOR"))) -> #DIV/0!
B11: =FINAL!A10 -> 2 | C11: =FINAL!B10 -> 0 | D11: =FINAL!C10 -> #DIV/0! | E11: PERIODO 01 | F11: =IF(D11<2.95,"BAJO",IF(D11<4,"BASICO",IF(D11<4.5,"ALTO","SUPERIOR"))) -> #DIV/0!
B12: =FINAL!A11 -> 3 | C12: =FINAL!B11 -> 0 | D12: =FINAL!C11 -> #DIV/0! | E12: PERIODO 01 | F12: =IF(D12<2.95,"BAJO",IF(D12<4,"BASICO",IF(D12<4.5,"ALTO","SUPERIOR"))) -> #DIV/0!
B13: =FINAL!A12 -> 4 | C13: =FINAL!B12 -> 0 | D13: =FINAL!C12 -> #DIV/0! | E13: PERIODO 01 | F13: =IF(D13<2.95,"BAJO",IF(D13<4,"BASICO",IF(D13<4.5,"ALTO","SUPERIOR"))) -> #DIV/0!
B14: =FINAL!A13 -> 5 | C14: =FINAL!B13 -> 0 | D14: =FINAL!C13 -> #DIV/0! | E14: PERIODO 01 | F14: =IF(D14<2.95,"BAJO",IF(D14<4,"BASICO",IF(D14<4.5,"ALTO","SUPERIOR"))) -> #DIV/0!
B15: =FINAL!A14 -> 6 | C15: =FINAL!B14 -> 0 | D15: =FINAL!C14 -> #DIV/0! | E15: PERIODO 01 | F15: =IF(D15<2.95,"BAJO",IF(D15<4,"BASICO",IF(D15<4.5,"ALTO","SUPERIOR"))) -> #DIV/0!
B16: =FINAL!A15 -> 7 | C16: =FINAL!B15 -> 0 | D16: =FINAL!C15 -> #DIV/0! | E16: PERIODO 01 | F16: =IF(D16<2.95,"BAJO",IF(D16<4,"BASICO",IF(D16<4.5,"ALTO","SUPERIOR"))) -> #DIV/0!
B17: =FINAL!A16 -> 8 | C17: =FINAL!B16 -> 0 | D17: =FINAL!C16 -> #DIV/0! | E17: PERIODO 01 | F17: =IF(D17<2.95,"BAJO",IF(D17<4,"BASICO",IF(D17<4.5,"ALTO","SUPERIOR"))) -> #DIV/0!
B18: =FINAL!A17 -> 9 | C18: =FINAL!B17 -> 0 | D18: =FINAL!C17 -> #DIV/0! | E18: PERIODO 01 | F18: =IF(D18<2.95,"BAJO",IF(D18<4,"BASICO",IF(D18<4.5,"ALTO","SUPERIOR"))) -> #DIV/0!
B19: =FINAL!A18 -> 10 | C19: =FINAL!B18 -> 0 | D19: =FINAL!C18 -> #DIV/0! | E19: PERIODO 01 | F19: =IF(D19<2.95,"BAJO",IF(D19<4,"BASICO",IF(D19<4.5,"ALTO","SUPERIOR"))) -> #DIV/0!
B20: =FINAL!A19 -> 11 | C20: =FINAL!B19 -> 0 | D20: =FINAL!C19 -> #DIV/0! | E20: PERIODO 01 | F20: =IF(D20<2.95,"BAJO",IF(D20<4,"BASICO",IF(D20<4.5,"ALTO","SUPERIOR"))) -> #DIV/0!
B21: =FINAL!A20 -> 12 | C21: =FINAL!B20 -> 0 | D21: =FINAL!C20 -> #DIV/0! | E21: PERIODO 01 | F21: =IF(D21<2.95,"BAJO",IF(D21<4,"BASICO",IF(D21<4.5,"ALTO","SUPERIOR"))) -> #DIV/0!
... B49: =FINAL!A48 -> 40 | C49: =FINAL!B48 -> 0 | D49: =FINAL!C48 -> #DIV/0! | E49: PERIODO 01 | F49: =IF(D49<2.95,"BAJO",IF(D49<4,"BASICO",IF(D49<4.5,"ALTO","SUPERIOR"))) -> #DIV/0!
B50: =B10 -> 1 | C50: =C10 -> 0 | D50: =FINAL!D9 -> #DIV/0! | E50: PERIODO 02 | F50: =IF(D50<2.95,"BAJO",IF(D50<4,"BASICO",IF(D50<4.5,"ALTO","SUPERIOR"))) -> #DIV/0!
B51: =B11 -> 2 | C51: =C11 -> 0 | D51: =FINAL!D10 -> #DIV/0! | E51: PERIODO 02 | F51: =IF(D51<2.95,"BAJO",IF(D51<4,"BASICO",IF(D51<4.5,"ALTO","SUPERIOR"))) -> #DIV/0!
B52: =B12 -> 3 | C52: =C12 -> 0 | D52: =FINAL!D11 -> #DIV/0! | E52: PERIODO 02 | F52: =IF(D52<2.95,"BAJO",IF(D52<4,"BASICO",IF(D52<4.5,"ALTO","SUPERIOR"))) -> #DIV/0!
B53: =B13 -> 4 | C53: =C13 -> 0 | D53: =FINAL!D12 -> #DIV/0! | E53: PERIODO 02 | F53: =IF(D53<2.95,"BAJO",IF(D53<4,"BASICO",IF(D53<4.5,"ALTO","SUPERIOR"))) -> #DIV/0!
B54: =B14 -> 5 | C54: =C14 -> 0 | D54: =FINAL!D13 -> #DIV/0! | E54: PERIODO 02 | F54: =IF(D54<2.95,"BAJO",IF(D54<4,"BASICO",IF(D54<4.5,"ALTO","SUPERIOR"))) -> #DIV/0!
B55: =B15 -> 6 | C55: =C15 -> 0 | D55: =FINAL!D14 -> #DIV/0! | E55: PERIODO 02 | F55: =IF(D55<2.95,"BAJO",IF(D55<4,"BASICO",IF(D55<4.5,"ALTO","SUPERIOR"))) -> #DIV/0!
B56: =B16 -> 7 | C56: =C16 -> 0 | D56: =FINAL!D15 -> #DIV/0! | E56: PERIODO 02 | F56: =IF(D56<2.95,"BAJO",IF(D56<4,"BASICO",IF(D56<4.5,"ALTO","SUPERIOR"))) -> #DIV/0!
B57: =B17 -> 8 | C57: =C17 -> 0 | D57: =FINAL!D16 -> #DIV/0! | E57: PERIODO 02 | F57: =IF(D57<2.95,"BAJO",IF(D57<4,"BASICO",IF(D57<4.5,"ALTO","SUPERIOR"))) -> #DIV/0!
B58: =B18 -> 9 | C58: =C18 -> 0 | D58: =FINAL!D17 -> #DIV/0! | E58: PERIODO 02 | F58: =IF(D58<2.95,"BAJO",IF(D58<4,"BASICO",IF(D58<4.5,"ALTO","SUPERIOR"))) -> #DIV/0!
B59: =B19 -> 10 | C59: =C19 -> 0 | D59: =FINAL!D18 -> #DIV/0! | E59: PERIODO 02 | F59: =IF(D59<2.95,"BAJO",IF(D59<4,"BASICO",IF(D59<4.5,"ALTO","SUPERIOR"))) -> #DIV/0!
B60: =B20 -> 11 | C60: =C20 -> 0 | D60: =FINAL!D19 -> #DIV/0! | E60: PERIODO 02 | F60: =IF(D60<2.95,"BAJO",IF(D60<4,"BASICO",IF(D60<4.5,"ALTO","SUPERIOR"))) -> #DIV/0!
B61: =B21 -> 12 | C61: =C21 -> 0 | D61: =FINAL!D20 -> #DIV/0! | E61: PERIODO 02 | F61: =IF(D61<2.95,"BAJO",IF(D61<4,"BASICO",IF(D61<4.5,"ALTO","SUPERIOR"))) -> #DIV/0!
... B89: =B49 -> 40 | C89: =C49 -> 0 | D89: =FINAL!D48 -> #DIV/0! | E89: PERIODO 02 | F89: =IF(D89<2.95,"BAJO",IF(D89<4,"BASICO",IF(D89<4.5,"ALTO","SUPERIOR"))) -> #DIV/0!
B90: =B10 -> 1 | C90: =C10 -> 0 | D90: =FINAL!E9 -> #DIV/0! | E90: PERIODO 03 | F90: =IF(D90<2.95,"BAJO",IF(D90<4,"BASICO",IF(D90<4.5,"ALTO","SUPERIOR"))) -> #DIV/0!
B91: =B11 -> 2 | C91: =C11 -> 0 | D91: =FINAL!E10 -> #DIV/0! | E91: PERIODO 03 | F91: =IF(D91<2.95,"BAJO",IF(D91<4,"BASICO",IF(D91<4.5,"ALTO","SUPERIOR"))) -> #DIV/0!
B92: =B12 -> 3 | C92: =C12 -> 0 | D92: =FINAL!E11 -> #DIV/0! | E92: PERIODO 03 | F92: =IF(D92<2.95,"BAJO",IF(D92<4,"BASICO",IF(D92<4.5,"ALTO","SUPERIOR"))) -> #DIV/0!
B93: =B13 -> 4 | C93: =C13 -> 0 | D93: =FINAL!E12 -> #DIV/0! | E93: PERIODO 03 | F93: =IF(D93<2.95,"BAJO",IF(D93<4,"BASICO",IF(D93<4.5,"ALTO","SUPERIOR"))) -> #DIV/0!
B94: =B14 -> 5 | C94: =C14 -> 0 | D94: =FINAL!E13 -> #DIV/0! | E94: PERIODO 03 | F94: =IF(D94<2.95,"BAJO",IF(D94<4,"BASICO",IF(D94<4.5,"ALTO","SUPERIOR"))) -> #DIV/0!
B95: =B15 -> 6 | C95: =C15 -> 0 | D95: =FINAL!E14 -> #DIV/0! | E95: PERIODO 03 | F95: =IF(D95<2.95,"BAJO",IF(D95<4,"BASICO",IF(D95<4.5,"ALTO","SUPERIOR"))) -> #DIV/0!
B96: =B16 -> 7 | C96: =C16 -> 0 | D96: =FINAL!E15 -> #DIV/0! | E96: PERIODO 03 | F96: =IF(D96<2.95,"BAJO",IF(D96<4,"BASICO",IF(D96<4.5,"ALTO","SUPERIOR"))) -> #DIV/0!
B97: =B17 -> 8 | C97: =C17 -> 0 | D97: =FINAL!E16 -> #DIV/0! | E97: PERIODO 03 | F97: =IF(D97<2.95,"BAJO",IF(D97<4,"BASICO",IF(D97<4.5,"ALTO","SUPERIOR"))) -> #DIV/0!
B98: =B18 -> 9 | C98: =C18 -> 0 | D98: =FINAL!E17 -> #DIV/0! | E98: PERIODO 03 | F98: =IF(D98<2.95,"BAJO",IF(D98<4,"BASICO",IF(D98<4.5,"ALTO","SUPERIOR"))) -> #DIV/0!
B99: =B19 -> 10 | C99: =C19 -> 0 | D99: =FINAL!E18 -> #DIV/0! | E99: PERIODO 03 | F99: =IF(D99<2.95,"BAJO",IF(D99<4,"BASICO",IF(D99<4.5,"ALTO","SUPERIOR"))) -> #DIV/0!
B100: =B20 -> 11 | C100: =C20 -> 0 | D100: =FINAL!E19 -> #DIV/0! | E100: PERIODO 03 | F100: =IF(D100<2.95,"BAJO",IF(D100<4,"BASICO",IF(D100<4.5,"ALTO","SUPERIOR"))) -> #DIV/0!
B101: =B21 -> 12 | C101: =C21 -> 0 | D101: =FINAL!E20 -> #DIV/0! | E101: PERIODO 03 | F101: =IF(D101<2.95,"BAJO",IF(D101<4,"BASICO",IF(D101<4.5,"ALTO","SUPERIOR"))) -> #DIV/0!
... B129: =B49 -> 40 | C129: =C49 -> 0 | D129: =FINAL!E48 -> #DIV/0! | E129: PERIODO 03 | F129: =IF(D129<2.95,"BAJO",IF(D129<4,"BASICO",IF(D129<4.5,"ALTO","SUPERIOR"))) -> #DIV/0!
...
